RPC_ERROR
Odoo Server Error
Traceback (most recent call last):
  File "/usr/lib/python3/dist-packages/odoo/tools/convert.py", line 564, in _tag_root
    f(rec)
  File "/usr/lib/python3/dist-packages/odoo/tools/convert.py", line 464, in _tag_record
    record = model._load_records([data], self.mode == 'update')
  File "/usr/lib/python3/dist-packages/odoo/models.py", line 5115, in _load_records
    records = self._load_records_create([data['values'] for data in to_create])
  File "/usr/lib/python3/dist-packages/odoo/models.py", line 5026, in _load_records_create
    return self.create(values)
  File "<decorator-gen-117>", line 2, in create
  File "/usr/lib/python3/dist-packages/odoo/api.py", line 431, in _model_create_multi
    return create(self, arg)
  File "/usr/lib/python3/dist-packages/odoo/addons/base/models/res_users.py", line 1502, in create
    groups = super().create(vals_list)
  File "<decorator-gen-115>", line 2, in create
  File "/usr/lib/python3/dist-packages/odoo/api.py", line 431, in _model_create_multi
    return create(self, arg)
  File "/usr/lib/python3/dist-packages/odoo/addons/base/models/res_users.py", line 1361, in create
    groups = super(GroupsImplied, self).create(vals_list)
  File "<decorator-gen-12>", line 2, in create
  File "/usr/lib/python3/dist-packages/odoo/api.py", line 431, in _model_create_multi
    return create(self, arg)
  File "/usr/lib/python3/dist-packages/odoo/models.py", line 4654, in create
    records = self._create(data_list)
  File "/usr/lib/python3/dist-packages/odoo/models.py", line 4842, in _create
    cr.execute(SQL(
  File "/usr/lib/python3/dist-packages/odoo/sql_db.py", line 332, in execute
    res = self._obj.execute(query, params)
psycopg2.errors.UniqueViolation: duplicate key value violates unique constraint "res_groups_name_uniq"
DETAIL:  Key (category_id, name)=(1, {"en_US": "NCF Manager"}) already exists.


The above exception was the direct cause of the following exception:

Traceback (most recent call last):
  File "/usr/lib/python3/dist-packages/odoo/http.py", line 1941, in _serve_db
    return service_model.retrying(self._serve_ir_http, self.env)
  File "/usr/lib/python3/dist-packages/odoo/service/model.py", line 152, in retrying
    result = func()
  File "/usr/lib/python3/dist-packages/odoo/http.py", line 1969, in _serve_ir_http
    response = self.dispatcher.dispatch(rule.endpoint, args)
  File "/usr/lib/python3/dist-packages/odoo/http.py", line 2173, in dispatch
    result = self.request.registry['ir.http']._dispatch(endpoint)
  File "/usr/lib/python3/dist-packages/odoo/addons/base/models/ir_http.py", line 221, in _dispatch
    result = endpoint(**request.params)
  File "/usr/lib/python3/dist-packages/odoo/http.py", line 778, in route_wrapper
    result = endpoint(self, *args, **params_ok)
  File "/usr/lib/python3/dist-packages/odoo/addons/web/controllers/dataset.py", line 29, in call_button
    action = self._call_kw(model, method, args, kwargs)
  File "/usr/lib/python3/dist-packages/odoo/addons/web/controllers/dataset.py", line 21, in _call_kw
    return call_kw(Model, method, args, kwargs)
  File "/usr/lib/python3/dist-packages/odoo/api.py", line 484, in call_kw
    result = _call_kw_multi(method, model, args, kwargs)
  File "/usr/lib/python3/dist-packages/odoo/api.py", line 469, in _call_kw_multi
    result = method(recs, *args, **kwargs)
  File "<decorator-gen-77>", line 2, in button_immediate_install
  File "/usr/lib/python3/dist-packages/odoo/addons/base/models/ir_module.py", line 75, in check_and_log
    return method(self, *args, **kwargs)
  File "/usr/lib/python3/dist-packages/odoo/addons/base/models/ir_module.py", line 469, in button_immediate_install
    return self._button_immediate_function(self.env.registry[self._name].button_install)
  File "/usr/lib/python3/dist-packages/odoo/addons/base/models/ir_module.py", line 593, in _button_immediate_function
    registry = modules.registry.Registry.new(self._cr.dbname, update_module=True)
  File "<decorator-gen-16>", line 2, in new
  File "/usr/lib/python3/dist-packages/odoo/tools/func.py", line 87, in locked
    return func(inst, *args, **kwargs)
  File "/usr/lib/python3/dist-packages/odoo/modules/registry.py", line 110, in new
    odoo.modules.load_modules(registry, force_demo, status, update_module)
  File "/usr/lib/python3/dist-packages/odoo/modules/loading.py", line 485, in load_modules
    processed_modules += load_marked_modules(env, graph,
  File "/usr/lib/python3/dist-packages/odoo/modules/loading.py", line 366, in load_marked_modules
    loaded, processed = load_module_graph(
  File "/usr/lib/python3/dist-packages/odoo/modules/loading.py", line 229, in load_module_graph
    load_data(env, idref, mode, kind='data', package=package)
  File "/usr/lib/python3/dist-packages/odoo/modules/loading.py", line 73, in load_data
    tools.convert_file(env, package.name, filename, idref, mode, noupdate, kind)
  File "/usr/lib/python3/dist-packages/odoo/tools/convert.py", line 635, in convert_file
    convert_xml_import(env, module, fp, idref, mode, noupdate)
  File "/usr/lib/python3/dist-packages/odoo/tools/convert.py", line 701, in convert_xml_import
    obj.parse(doc.getroot())
  File "/usr/lib/python3/dist-packages/odoo/tools/convert.py", line 621, in parse
    self._tag_root(de)
  File "/usr/lib/python3/dist-packages/odoo/tools/convert.py", line 577, in _tag_root
    raise ParseError('while parsing %s:%s, somewhere inside\n%s' % (
odoo.tools.convert.ParseError: while parsing /var/lib/odoo/addons/17.0/ncf_module/security/security.xml:12, somewhere inside
<record id="group_ncf_manager" model="res.groups">
        <field name="name">NCF Manager</field>
        <field name="category_id" ref="base.module_category_accounting"/>
        <field name="implied_ids" eval="[(4, ref('group_ncf_user')), (4, ref('account.group_account_manager'))]"/>
        <field name="comment">Users can manage NCF sequences and configuration</field>
    </record>

The above server error caused the following client error:
RPC_ERROR: Odoo Server Error
    RPC_ERROR
        at makeErrorFromResponse (https://huevosnana.sp.weppa.dev/web/assets/f0e6003/web.assets_web.min.js:2946:163)
        at XMLHttpRequest.<anonymous> (https://huevosnana.sp.weppa.dev/web/assets/f0e6003/web.assets_web.min.js:2950:13)