RPC_ERROR
Odoo Server Error
Traceback (most recent call last):
  File "/usr/lib/python3/dist-packages/odoo/http.py", line 1941, in _serve_db
    return service_model.retrying(self._serve_ir_http, self.env)
  File "/usr/lib/python3/dist-packages/odoo/service/model.py", line 152, in retrying
    result = func()
  File "/usr/lib/python3/dist-packages/odoo/http.py", line 1969, in _serve_ir_http
    response = self.dispatcher.dispatch(rule.endpoint, args)
  File "/usr/lib/python3/dist-packages/odoo/http.py", line 2173, in dispatch
    result = self.request.registry['ir.http']._dispatch(endpoint)
  File "/usr/lib/python3/dist-packages/odoo/addons/base/models/ir_http.py", line 221, in _dispatch
    result = endpoint(**request.params)
  File "/usr/lib/python3/dist-packages/odoo/http.py", line 778, in route_wrapper
    result = endpoint(self, *args, **params_ok)
  File "/usr/lib/python3/dist-packages/odoo/addons/web/controllers/dataset.py", line 29, in call_button
    action = self._call_kw(model, method, args, kwargs)
  File "/usr/lib/python3/dist-packages/odoo/addons/web/controllers/dataset.py", line 21, in _call_kw
    return call_kw(Model, method, args, kwargs)
  File "/usr/lib/python3/dist-packages/odoo/api.py", line 484, in call_kw
    result = _call_kw_multi(method, model, args, kwargs)
  File "/usr/lib/python3/dist-packages/odoo/api.py", line 469, in _call_kw_multi
    result = method(recs, *args, **kwargs)
  File "<decorator-gen-77>", line 2, in button_immediate_install
  File "/usr/lib/python3/dist-packages/odoo/addons/base/models/ir_module.py", line 75, in check_and_log
    return method(self, *args, **kwargs)
  File "/usr/lib/python3/dist-packages/odoo/addons/base/models/ir_module.py", line 469, in button_immediate_install
    return self._button_immediate_function(self.env.registry[self._name].button_install)
  File "/usr/lib/python3/dist-packages/odoo/addons/base/models/ir_module.py", line 593, in _button_immediate_function
    registry = modules.registry.Registry.new(self._cr.dbname, update_module=True)
  File "<decorator-gen-16>", line 2, in new
  File "/usr/lib/python3/dist-packages/odoo/tools/func.py", line 87, in locked
    return func(inst, *args, **kwargs)
  File "/usr/lib/python3/dist-packages/odoo/modules/registry.py", line 110, in new
    odoo.modules.load_modules(registry, force_demo, status, update_module)
  File "/usr/lib/python3/dist-packages/odoo/modules/loading.py", line 485, in load_modules
    processed_modules += load_marked_modules(env, graph,
  File "/usr/lib/python3/dist-packages/odoo/modules/loading.py", line 366, in load_marked_modules
    loaded, processed = load_module_graph(
  File "/usr/lib/python3/dist-packages/odoo/modules/loading.py", line 229, in load_module_graph
    load_data(env, idref, mode, kind='data', package=package)
  File "/usr/lib/python3/dist-packages/odoo/modules/loading.py", line 73, in load_data
    tools.convert_file(env, package.name, filename, idref, mode, noupdate, kind)
  File "/usr/lib/python3/dist-packages/odoo/tools/convert.py", line 635, in convert_file
    convert_xml_import(env, module, fp, idref, mode, noupdate)
  File "/usr/lib/python3/dist-packages/odoo/tools/convert.py", line 701, in convert_xml_import
    obj.parse(doc.getroot())
  File "/usr/lib/python3/dist-packages/odoo/tools/convert.py", line 621, in parse
    self._tag_root(de)
  File "/usr/lib/python3/dist-packages/odoo/tools/convert.py", line 575, in _tag_root
    raise ParseError(msg) from None  # Restart with "--log-handler odoo.tools.convert:DEBUG" for complete traceback
odoo.tools.convert.ParseError: while parsing /var/lib/odoo/addons/17.0/ncf_management/reports/dgii_reports_views.xml:82
Ocurri√≥ un error al validar la vista cercana a:

                                </field>
                        </page>
                    </notebook>
                    
                    <field name="currency_id" invisible="1"/>

El campo "ncf_number" no existe en el modelo "dgii.report.607.line"

View error context:
{'file': '/var/lib/odoo/addons/17.0/ncf_management/reports/dgii_reports_views.xml',
 'line': 52,
 'name': 'dgii.report.607.form',
 'view': ir.ui.view(1520,),
 'view.model': 'dgii.report.607',
 'view.parent': ir.ui.view(),
 'xmlid': 'view_dgii_report_607_form'}


The above server error caused the following client error:
RPC_ERROR: Odoo Server Error
    RPC_ERROR
        at makeErrorFromResponse (https://huevosnana.sp.weppa.dev/web/assets/f0e6003/web.assets_web.min.js:2946:163)
        at XMLHttpRequest.<anonymous> (https://huevosnana.sp.weppa.dev/web/assets/f0e6003/web.assets_web.min.js:2950:13)